<?xml version="1.0" ?>
<!-- =================================================================================== -->
<!-- |    This document was autogenerated by xacro from irb120.xacro                   | -->
<!-- |    EDITING THIS FILE BY HAND IS NOT RECOMMENDED                                 | -->
<!-- =================================================================================== -->
<robot name="abb_irb120" xmlns:xacro="http://ros.org/wiki/xacro">
  <!-- link list -->
  <link name="base_link">
    <inertial>
      <mass value="0"/>
      <!-- static base, disable dynamics for this link -->
      <origin rpy="0 0 0" xyz="0 0 0.055"/>
      <inertia ixx="0.00381666666667" ixy="0" ixz="0" iyy="0.0036" iyz="0" izz="0.00381666666667"/>
    </inertial>
    <visual>
      <origin rpy="0 0 0" xyz="0 0 0"/>
      <geometry>
        <!-- <mesh filename="meshes/irb120/visual/base_link.stl" scale="0.0254 0.0254 0.0254"/> -->
        <mesh filename="meshes/irb120/visual/base_link.stl"/>
      </geometry>
      <material name="abb_orange">
        <color rgba="1 0.43 0 1"/>
      </material>
    </visual>
    <collision>
      <origin rpy="0 0 0" xyz="0 0 0"/>
      <geometry>
        <mesh filename="meshes/irb120/collision/base_link.stl"/>
      </geometry>
      <material name="cyan">
        <color rgba="0 1 1 1"/>
      </material>
    </collision>
    <!-- <inertial>
      <mass value="7.731"/>
      <inertia ixx="0.02551918" ixy="-3.692e-005" ixz="0.00037463" iyy="0.02641777" iyz="4.26e-006" izz="0.02180975"/>
      <origin rpy="0 0 0" xyz="0.003 6e-5 0.08978"/>
    </inertial> -->
  </link>
  <link name="link_1">
    <visual>
      <origin rpy="0 0 0" xyz="0 0 -0.163"/>
      <geometry>
        <mesh filename="meshes/irb120/visual/link_1.stl"/>
      </geometry>
      <material name="abb_orange"/>
    </visual>
    <collision>
      <origin rpy="0 0 0" xyz="0 0 -0.163"/>
      <geometry>
        <mesh filename="meshes/irb120/collision/link_1.stl"/>
      </geometry>
      <material name="cyan"/>
    </collision>
    <inertial>
      <mass value="6.004000e+00"/>
      <inertia ixx="3.193406e-02" ixy="1.445000e-05" ixz="-3.272200e-04" iyy="2.637650e-02" iyz="-3.322410e-03" izz="2.386651e-02"/>
      <origin rpy="0 0 0" xyz="6.400000e-04 -1.898000e-02 9.504000e-02"/>
    </inertial>
  </link>
  <link name="link_2">
    <visual>
      <origin rpy="0 0 0" xyz="0 0 0"/>
      <geometry>
        <mesh filename="meshes/irb120/visual/link_2.stl"/>
      </geometry>
      <material name="abb_orange"/>
    </visual>
    <collision>
      <origin rpy="0 0 0" xyz="0 0 0"/>
      <geometry>
        <mesh filename="meshes/irb120/collision/link_2.stl"/>
      </geometry>
      <material name="cyan"/>
    </collision>
    <inertial>
      <mass value="4.187000e+00"/>
      <inertia ixx="4.819772e-02" ixy="9.786000e-05" ixz="8.335000e-04" iyy="4.032172e-02" iyz="8.157000e-04" izz="1.476244e-02"/>
      <origin rpy="0 0 0" xyz="4.270000e-03 -2.943000e-02 1.420400e-01"/>
    </inertial>
  </link>
  <link name="link_3">
    <visual>
      <origin rpy="0 0 0" xyz="0 0 0"/>
      <geometry>
        <mesh filename="meshes/irb120/visual/link_3.stl"/>
      </geometry>
      <material name="abb_orange"/>
    </visual>
    <collision>
      <origin rpy="0 0 0" xyz="0 0 0"/>
      <geometry>
        <mesh filename="meshes/irb120/collision/link_3.stl"/>
      </geometry>
      <material name="cyan"/>
    </collision>
    <inertial>
      <mass value="3.173000e+00"/>
      <inertia ixx="6.184840e-03" ixy="-1.183800e-04" ixz="1.878090e-03" iyy="1.540900e-02" iyz="5.370000e-06" izz="1.311689e-02"/>
      <origin rpy="0 0 0" xyz="4.156000e-02 4.900000e-04 5.320000e-02"/>
    </inertial>
  </link>
  <link name="link_4">
    <visual>
      <origin rpy="0 0 0" xyz="-0.142 0 0"/>
      <geometry>
        <mesh filename="meshes/irb120/visual/link_4.stl"/>
      </geometry>
      <material name="abb_orange"/>
    </visual>
    <collision>
      <origin rpy="0 0 0" xyz="-0.142 0 0"/>
      <geometry>
        <mesh filename="meshes/irb120/collision/link_4.stl"/>
      </geometry>
      <material name="cyan"/>
    </collision>
    <inertial>
      <mass value="1.834000e+00"/>
      <inertia ixx="2.705740e-03" ixy="1.267490e-03" ixz="2.493700e-04" iyy="6.155200e-03" iyz="1.437600e-04" izz="7.059200e-03"/>
      <origin rpy="0 0 0" xyz="8.137000e-02 1.683000e-02 -4.330000e-03"/>
    </inertial>
  </link>
  <link name="link_5">
    <visual>
      <origin rpy="0 0 0" xyz="0 0 0"/>
      <geometry>
        <mesh filename="meshes/irb120/visual/link_5.stl"/>
      </geometry>
      <material name="abb_orange"/>
    </visual>
    <collision>
      <origin rpy="0 0 0" xyz="0 0 0"/>
      <geometry>
        <mesh filename="meshes/irb120/collision/link_5.stl"/>
      </geometry>
      <material name="cyan"/>
    </collision>
    <inertial>
      <mass value="1.271000e+00"/>
      <inertia ixx="7.580000e-04" ixy="-2.620000e-05" ixz="-3.370000e-05" iyy="2.034000e-03" iyz="6.300000e-06" izz="1.921000e-03"/>
      <origin rpy="0 0 0" xyz="1.155000e-02 1.370000e-03 1.010000e-03"/>
    </inertial>
  </link>
  <link name="link_6">
    <visual>
      <origin rpy="0 0 0" xyz="0 0 0"/>
      <geometry>
        <mesh filename="meshes/irb120/visual/link_6.stl"/>
      </geometry>
      <material name="black">
        <color rgba="0 0 0 1"/>
      </material>
    </visual>
    <collision>
      <origin rpy="0 0 0" xyz="0 0 0"/>
      <geometry>
        <mesh filename="meshes/irb120/collision/link_6.stl"/>
      </geometry>
      <material name="cyan"/>
    </collision>
    <inertial>
      <mass value="2.260000e-01"/>
      <inertia ixx="6.800000e-05" ixy="-1.000000e-07" ixz="0.000000e+00" iyy="4.100000e-05" iyz="0.000000e+00" izz="4.100000e-05"/>
      <origin rpy="0 0 0" xyz="-1.141100e-02 -8.000000e-05 -1.000000e-06"/>
    </inertial>
  </link>
  <link name="tool0"/>
  <!-- end of link list -->
  <!-- joint list -->
  <joint name="joint_1" type="revolute">
    <origin rpy="0 0 0" xyz="0 0 0.163"/>
    <parent link="base_link"/>
    <child link="link_1"/>
    <limit effort="76.6056808" lower="-2.87979326579" upper="2.87979326579" velocity="4.36332"/>
    <axis xyz="0 0 1"/>
    <dynamics damping="2.938521905" friction="16.6010185"/>
  </joint>
  <joint name="joint_2" type="revolute">
    <origin rpy="0 0 0" xyz="0 0 0.127"/>
    <parent link="link_1"/>
    <child link="link_2"/>
    <limit effort="66.795993" lower="-1.91986217719" upper="1.91986217719" velocity="4.36332"/>
    <axis xyz="0 1 0"/>
    <dynamics damping="3.692504123" friction="16.81295"/>
  </joint>
  <joint name="joint_3" type="revolute">
    <origin rpy="0 0 0" xyz="0 0 0.27"/>
    <parent link="link_2"/>
    <child link="link_3"/>
    <limit effort="32.824192" lower="-1.91986217719" upper="1.2217304764" velocity="4.36332"/>
    <axis xyz="0 1 0"/>
    <dynamics damping="1.516664278" friction="12.354825"/>
  </joint>
  <joint name="joint_4" type="revolute">
    <origin rpy="0 0 0" xyz="0.142 0 0.07"/>
    <parent link="link_3"/>
    <child link="link_4"/>
    <limit effort="7.32805" lower="-2.79252680319" upper="2.79252680319" velocity="5.58505"/>
    <axis xyz="1 0 0"/>
    <dynamics damping="0.44104375" friction="0.304825"/>
  </joint>
  <joint name="joint_5" type="revolute">
    <origin rpy="0 0 0" xyz="0.16 0 0"/>
    <parent link="link_4"/>
    <child link="link_5"/>
    <limit effort="6.552888" lower="-2.09439510239" upper="2.09439510239" velocity="5.58505"/>
    <axis xyz="0 1 0"/>
    <dynamics damping="0.4588619175" friction="2.41128"/>
  </joint>
  <joint name="joint_6" type="revolute">
    <origin rpy="0 0 0" xyz="0.072 0 0"/>
    <parent link="link_5"/>
    <child link="link_6"/>
    <limit effort="10.03295" lower="-6.98131700798" upper="6.98131700798" velocity="7.33038"/>
    <axis xyz="1 0 0"/>
    <dynamics damping="0.24524" friction="1.33985"/>
  </joint>
  <joint name="joint6-tool0" type="fixed">
    <parent link="link_6"/>
    <child link="tool0"/>
    <origin rpy="0 1.57079632679 0" xyz="0 0 0"/>
  </joint>
  <!-- end of joint list -->
</robot>
